Workbook

Sheet 00_Dashboard
B2: Osszes Ido [Auto] | E2: Top Kategoriak – aktualis honap [Auto] | H2: 6 Honapos Trend [Auto]
B3: Osszes Bevetel (HUF) | C3: =SUMIFS('01_Transactions'!L:L,'01_Transactions'!B:B,"Income") -> 0 | E3: =IFERROR('90_Settings'!B2,"") -> 0 | F3: =IFERROR(SUMPRODUCT(('01_Transactions'!F$2:F$5000='90_Settings'!B2)*(YEAR('01_Transactions'!A$2:A$5000)=YEAR(DATE(YEAR(TODAY()),MONTH(TODAY()),1)))*(MONTH('01_Transactions'!A$2:A$5000)=MONTH(DATE(YEAR(TODAY()),MONTH(TODAY()),1)))*'01_Transactions'!L$2:L$5000),0) -> 0 | I3: =TEXT(DATE(YEAR(TODAY()),MONTH(TODAY())+(-5),1),"YYYY-MM") -> 0 | J3: =TEXT(DATE(YEAR(TODAY()),MONTH(TODAY())+(-4),1),"YYYY-MM") -> 0 | K3: =TEXT(DATE(YEAR(TODAY()),MONTH(TODAY())+(-3),1),"YYYY-MM") -> 0 | L3: =TEXT(DATE(YEAR(TODAY()),MONTH(TODAY())+(-2),1),"YYYY-MM") -> 0 | M3: =TEXT(DATE(YEAR(TODAY()),MONTH(TODAY())+(-1),1),"YYYY-MM") -> 0 | N3: =TEXT(DATE(YEAR(TODAY()),MONTH(TODAY()),1),"YYYY-MM") -> 0
B4: Osszes Kiadas (HUF) | C4: =SUMIFS('01_Transactions'!L:L,'01_Transactions'!B:B,"Expense") -> 0 | E4: =IFERROR('90_Settings'!B3,"") -> 0 | F4: =IFERROR(SUMPRODUCT(('01_Transactions'!F$2:F$5000='90_Settings'!B3)*(YEAR('01_Transactions'!A$2:A$5000)=YEAR(DATE(YEAR(TODAY()),MONTH(TODAY()),1)))*(MONTH('01_Transactions'!A$2:A$5000)=MONTH(DATE(YEAR(TODAY()),MONTH(TODAY()),1)))*'01_Transactions'!L$2:L$5000),0) -> 0 | H4: Bevetel | I4: =SUMPRODUCT(('01_Transactions'!B$2:B$5000="Income")*(YEAR('01_Transactions'!A$2:A$5000)=YEAR(DATE(YEAR(TODAY()),MONTH(TODAY())+(-5),1)))*(MONTH('01_Transactions'!A$2:A$5000)=MONTH(DATE(YEAR(TODAY()),MONTH(TODAY())+(-5),1)))*'01_Transactions'!L$2:L$5000) -> 0 | J4: =SUMPRODUCT(('01_Transactions'!B$2:B$5000="Income")*(YEAR('01_Transactions'!A$2:A$5000)=YEAR(DATE(YEAR(TODAY()),MONTH(TODAY())+(-4),1)))*(MONTH('01_Transactions'!A$2:A$5000)=MONTH(DATE(YEAR(TODAY()),MONTH(TODAY())+(-4),1)))*'01_Transactions'!L$2:L$5000) -> 0 | K4: =SUMPRODUCT(('01_Transactions'!B$2:B$5000="Income")*(YEAR('01_Transactions'!A$2:A$5000)=YEAR(DATE(YEAR(TODAY()),MONTH(TODAY())+(-3),1)))*(MONTH('01_Transactions'!A$2:A$5000)=MONTH(DATE(YEAR(TODAY()),MONTH(TODAY())+(-3),1)))*'01_Transactions'!L$2:L$5000) -> 0 | L4: =SUMPRODUCT(('01_Transactions'!B$2:B$5000="Income")*(YEAR('01_Transactions'!A$2:A$5000)=YEAR(DATE(YEAR(TODAY()),MONTH(TODAY())+(-2),1)))*(MONTH('01_Transactions'!A$2:A$5000)=MONTH(DATE(YEAR(TODAY()),MONTH(TODAY())+(-2),1)))*'01_Transactions'!L$2:L$5000) -> 0 | M4: =SUMPRODUCT(('01_Transactions'!B$2:B$5000="Income")*(YEAR('01_Transactions'!A$2:A$5000)=YEAR(DATE(YEAR(TODAY()),MONTH(TODAY())+(-1),1)))*(MONTH('01_Transactions'!A$2:A$5000)=MONTH(DATE(YEAR(TODAY()),MONTH(TODAY())+(-1),1)))*'01_Transactions'!L$2:L$5000) -> 0 | N4: =SUMPRODUCT(('01_Transactions'!B$2:B$5000="Income")*(YEAR('01_Transactions'!A$2:A$5000)=YEAR(DATE(YEAR(TODAY()),MONTH(TODAY()),1)))*(MONTH('01_Transactions'!A$2:A$5000)=MONTH(DATE(YEAR(TODAY()),MONTH(TODAY()),1)))*'01_Transactions'!L$2:L$5000) -> 0
B5: Netto Vagyon (HUF) | C5: =C3-C4 -> 0 | E5: =IFERROR('90_Settings'!B4,"") -> 0 | F5: =IFERROR(SUMPRODUCT(('01_Transactions'!F$2:F$5000='90_Settings'!B4)*(YEAR('01_Transactions'!A$2:A$5000)=YEAR(DATE(YEAR(TODAY()),MONTH(TODAY()),1)))*(MONTH('01_Transactions'!A$2:A$5000)=MONTH(DATE(YEAR(TODAY()),MONTH(TODAY()),1)))*'01_Transactions'!L$2:L$5000),0) -> 0 | H5: Kiadas | I5: =SUMPRODUCT(('01_Transactions'!B$2:B$5000="Expense")*(YEAR('01_Transactions'!A$2:A$5000)=YEAR(DATE(YEAR(TODAY()),MONTH(TODAY())+(-5),1)))*(MONTH('01_Transactions'!A$2:A$5000)=MONTH(DATE(YEAR(TODAY()),MONTH(TODAY())+(-5),1)))*'01_Transactions'!L$2:L$5000) -> 0 | J5: =SUMPRODUCT(('01_Transactions'!B$2:B$5000="Expense")*(YEAR('01_Transactions'!A$2:A$5000)=YEAR(DATE(YEAR(TODAY()),MONTH(TODAY())+(-4),1)))*(MONTH('01_Transactions'!A$2:A$5000)=MONTH(DATE(YEAR(TODAY()),MONTH(TODAY())+(-4),1)))*'01_Transactions'!L$2:L$5000) -> 0 | K5: =SUMPRODUCT(('01_Transactions'!B$2:B$5000="Expense")*(YEAR('01_Transactions'!A$2:A$5000)=YEAR(DATE(YEAR(TODAY()),MONTH(TODAY())+(-3),1)))*(MONTH('01_Transactions'!A$2:A$5000)=MONTH(DATE(YEAR(TODAY()),MONTH(TODAY())+(-3),1)))*'01_Transactions'!L$2:L$5000) -> 0 | L5: =SUMPRODUCT(('01_Transactions'!B$2:B$5000="Expense")*(YEAR('01_Transactions'!A$2:A$5000)=YEAR(DATE(YEAR(TODAY()),MONTH(TODAY())+(-2),1)))*(MONTH('01_Transactions'!A$2:A$5000)=MONTH(DATE(YEAR(TODAY()),MONTH(TODAY())+(-2),1)))*'01_Transactions'!L$2:L$5000) -> 0 | M5: =SUMPRODUCT(('01_Transactions'!B$2:B$5000="Expense")*(YEAR('01_Transactions'!A$2:A$5000)=YEAR(DATE(YEAR(TODAY()),MONTH(TODAY())+(-1),1)))*(MONTH('01_Transactions'!A$2:A$5000)=MONTH(DATE(YEAR(TODAY()),MONTH(TODAY())+(-1),1)))*'01_Transactions'!L$2:L$5000) -> 0 | N5: =SUMPRODUCT(('01_Transactions'!B$2:B$5000="Expense")*(YEAR('01_Transactions'!A$2:A$5000)=YEAR(DATE(YEAR(TODAY()),MONTH(TODAY()),1)))*(MONTH('01_Transactions'!A$2:A$5000)=MONTH(DATE(YEAR(TODAY()),MONTH(TODAY()),1)))*'01_Transactions'!L$2:L$5000) -> 0
E6: =IFERROR('90_Settings'!B5,"") -> 0 | F6: =IFERROR(SUMPRODUCT(('01_Transactions'!F$2:F$5000='90_Settings'!B5)*(YEAR('01_Transactions'!A$2:A$5000)=YEAR(DATE(YEAR(TODAY()),MONTH(TODAY()),1)))*(MONTH('01_Transactions'!A$2:A$5000)=MONTH(DATE(YEAR(TODAY()),MONTH(TODAY()),1)))*'01_Transactions'!L$2:L$5000),0) -> 0 | H6: Cashflow | I6: =SUMPRODUCT(('01_Transactions'!B$2:B$5000="Income")*(YEAR('01_Transactions'!A$2:A$5000)=YEAR(DATE(YEAR(TODAY()),MONTH(TODAY())+(-5),1)))*(MONTH('01_Transactions'!A$2:A$5000)=MONTH(DATE(YEAR(TODAY()),MONTH(TODAY())+(-5),1)))*'01_Transactions'!L$2:L$5000)-SUMPRODUCT(('01_Transactions'!B$2:B$5000="Expense")*(YEAR('01_Transactions'!A$2:A$5000)=YEAR(DATE(YEAR(TODAY()),MONTH(TODAY())+(-5),1)))*(MONTH('01_Transactions'!A$2:A$5000)=MONTH(DATE(YEAR(TODAY()),MONTH(TODAY())+(-5),1)))*'01_Transactions'!L$2:L$5000) -> 0 | J6: =SUMPRODUCT(('01_Transactions'!B$2:B$5000="Income")*(YEAR('01_Transactions'!A$2:A$5000)=YEAR(DATE(YEAR(TODAY()),MONTH(TODAY())+(-4),1)))*(MONTH('01_Transactions'!A$2:A$5000)=MONTH(DATE(YEAR(TODAY()),MONTH(TODAY())+(-4),1)))*'01_Transactions'!L$2:L$5000)-SUMPRODUCT(('01_Transactions'!B$2:B$5000="Expense")*(YEAR('01_Transactions'!A$2:A$5000)=YEAR(DATE(YEAR(TODAY()),MONTH(TODAY())+(-4),1)))*(MONTH('01_Transactions'!A$2:A$5000)=MONTH(DATE(YEAR(TODAY()),MONTH(TODAY())+(-4),1)))*'01_Transactions'!L$2:L$5000) -> 0 | K6: =SUMPRODUCT(('01_Transactions'!B$2:B$5000="Income")*(YEAR('01_Transactions'!A$2:A$5000)=YEAR(DATE(YEAR(TODAY()),MONTH(TODAY())+(-3),1)))*(MONTH('01_Transactions'!A$2:A$5000)=MONTH(DATE(YEAR(TODAY()),MONTH(TODAY())+(-3),1)))*'01_Transactions'!L$2:L$5000)-SUMPRODUCT(('01_Transactions'!B$2:B$5000="Expense")*(YEAR('01_Transactions'!A$2:A$5000)=YEAR(DATE(YEAR(TODAY()),MONTH(TODAY())+(-3),1)))*(MONTH('01_Transactions'!A$2:A$5000)=MONTH(DATE(YEAR(TODAY()),MONTH(TODAY())+(-3),1)))*'01_Transactions'!L$2:L$5000) -> 0 | L6: =SUMPRODUCT(('01_Transactions'!B$2:B$5000="Income")*(YEAR('01_Transactions'!A$2:A$5000)=YEAR(DATE(YEAR(TODAY()),MONTH(TODAY())+(-2),1)))*(MONTH('01_Transactions'!A$2:A$5000)=MONTH(DATE(YEAR(TODAY()),MONTH(TODAY())+(-2),1)))*'01_Transactions'!L$2:L$5000)-SUMPRODUCT(('01_Transactions'!B$2:B$5000="Expense")*(YEAR('01_Transactions'!A$2:A$5000)=YEAR(DATE(YEAR(TODAY()),MONTH(TODAY())+(-2),1)))*(MONTH('01_Transactions'!A$2:A$5000)=MONTH(DATE(YEAR(TODAY()),MONTH(TODAY())+(-2),1)))*'01_Transactions'!L$2:L$5000) -> 0 | M6: =SUMPRODUCT(('01_Transactions'!B$2:B$5000="Income")*(YEAR('01_Transactions'!A$2:A$5000)=YEAR(DATE(YEAR(TODAY()),MONTH(TODAY())+(-1),1)))*(MONTH('01_Transactions'!A$2:A$5000)=MONTH(DATE(YEAR(TODAY()),MONTH(TODAY())+(-1),1)))*'01_Transactions'!L$2:L$5000)-SUMPRODUCT(('01_Transactions'!B$2:B$5000="Expense")*(YEAR('01_Transactions'!A$2:A$5000)=YEAR(DATE(YEAR(TODAY()),MONTH(TODAY())+(-1),1)))*(MONTH('01_Transactions'!A$2:A$5000)=MONTH(DATE(YEAR(TODAY()),MONTH(TODAY())+(-1),1)))*'01_Transactions'!L$2:L$5000) -> 0 | N6: =SUMPRODUCT(('01_Transactions'!B$2:B$5000="Income")*(YEAR('01_Transactions'!A$2:A$5000)=YEAR(DATE(YEAR(TODAY()),MONTH(TODAY()),1)))*(MONTH('01_Transactions'!A$2:A$5000)=MONTH(DATE(YEAR(TODAY()),MONTH(TODAY()),1)))*'01_Transactions'!L$2:L$5000)-SUMPRODUCT(('01_Transactions'!B$2:B$5000="Expense")*(YEAR('01_Transactions'!A$2:A$5000)=YEAR(DATE(YEAR(TODAY()),MONTH(TODAY()),1)))*(MONTH('01_Transactions'!A$2:A$5000)=MONTH(DATE(YEAR(TODAY()),MONTH(TODAY()),1)))*'01_Transactions'!L$2:L$5000) -> 0
B7: Aktualis Honap [Auto] | E7: =IFERROR('90_Settings'!B6,"") -> 0 | F7: =IFERROR(SUMPRODUCT(('01_Transactions'!F$2:F$5000='90_Settings'!B6)*(YEAR('01_Transactions'!A$2:A$5000)=YEAR(DATE(YEAR(TODAY()),MONTH(TODAY()),1)))*(MONTH('01_Transactions'!A$2:A$5000)=MONTH(DATE(YEAR(TODAY()),MONTH(TODAY()),1)))*'01_Transactions'!L$2:L$5000),0) -> 0
B8: Havi Bevetel | C8: =SUMPRODUCT(('01_Transactions'!B$2:B$5000="Income")*(YEAR('01_Transactions'!A$2:A$5000)=YEAR(DATE(YEAR(TODAY()),MONTH(TODAY()),1)))*(MONTH('01_Transactions'!A$2:A$5000)=MONTH(DATE(YEAR(TODAY()),MONTH(TODAY()),1)))*'01_Transactions'!L$2:L$5000) -> 0 | E8: =IFERROR('90_Settings'!B7,"") -> 0 | F8: =IFERROR(SUMPRODUCT(('01_Transactions'!F$2:F$5000='90_Settings'!B7)*(YEAR('01_Transactions'!A$2:A$5000)=YEAR(DATE(YEAR(TODAY()),MONTH(TODAY()),1)))*(MONTH('01_Transactions'!A$2:A$5000)=MONTH(DATE(YEAR(TODAY()),MONTH(TODAY()),1)))*'01_Transactions'!L$2:L$5000),0) -> 0 | H8: Kategoriak – 6 honapos bontasban [Auto]
B9: Havi Kiadas | C9: =SUMPRODUCT(('01_Transactions'!B$2:B$5000="Expense")*(YEAR('01_Transactions'!A$2:A$5000)=YEAR(DATE(YEAR(TODAY()),MONTH(TODAY()),1)))*(MONTH('01_Transactions'!A$2:A$5000)=MONTH(DATE(YEAR(TODAY()),MONTH(TODAY()),1)))*'01_Transactions'!L$2:L$5000) -> 0 | H9: Kategoria | I9: =TEXT(DATE(YEAR(TODAY()),MONTH(TODAY())+(-5),1),"YYYY-MM") -> 0 | J9: =TEXT(DATE(YEAR(TODAY()),MONTH(TODAY())+(-4),1),"YYYY-MM") -> 0 | K9: =TEXT(DATE(YEAR(TODAY()),MONTH(TODAY())+(-3),1),"YYYY-MM") -> 0 | L9: =TEXT(DATE(YEAR(TODAY()),MONTH(TODAY())+(-2),1),"YYYY-MM") -> 0 | M9: =TEXT(DATE(YEAR(TODAY()),MONTH(TODAY())+(-1),1),"YYYY-MM") -> 0 | N9: =TEXT(DATE(YEAR(TODAY()),MONTH(TODAY()),1),"YYYY-MM") -> 0
B10: Havi Cashflow | C10: =C8-C9 -> 0 | E10: Virtualis Zsebek [Auto] | H10: =IFERROR('90_Settings'!B2,"") -> 0 | I10: =IFERROR(SUMPRODUCT(('01_Transactions'!F$2:F$5000='90_Settings'!B2)*(YEAR('01_Transactions'!A$2:A$5000)=YEAR(DATE(YEAR(TODAY()),MONTH(TODAY())+(-5),1)))*(MONTH('01_Transactions'!A$2:A$5000)=MONTH(DATE(YEAR(TODAY()),MONTH(TODAY())+(-5),1)))*'01_Transactions'!L$2:L$5000),0) -> 0 | J10: =IFERROR(SUMPRODUCT(('01_Transactions'!F$2:F$5000='90_Settings'!B2)*(YEAR('01_Transactions'!A$2:A$5000)=YEAR(DATE(YEAR(TODAY()),MONTH(TODAY())+(-4),1)))*(MONTH('01_Transactions'!A$2:A$5000)=MONTH(DATE(YEAR(TODAY()),MONTH(TODAY())+(-4),1)))*'01_Transactions'!L$2:L$5000),0) -> 0 | K10: =IFERROR(SUMPRODUCT(('01_Transactions'!F$2:F$5000='90_Settings'!B2)*(YEAR('01_Transactions'!A$2:A$5000)=YEAR(DATE(YEAR(TODAY()),MONTH(TODAY())+(-3),1)))*(MONTH('01_Transactions'!A$2:A$5000)=MONTH(DATE(YEAR(TODAY()),MONTH(TODAY())+(-3),1)))*'01_Transactions'!L$2:L$5000),0) -> 0 | L10: =IFERROR(SUMPRODUCT(('01_Transactions'!F$2:F$5000='90_Settings'!B2)*(YEAR('01_Transactions'!A$2:A$5000)=YEAR(DATE(YEAR(TODAY()),MONTH(TODAY())+(-2),1)))*(MONTH('01_Transactions'!A$2:A$5000)=MONTH(DATE(YEAR(TODAY()),MONTH(TODAY())+(-2),1)))*'01_Transactions'!L$2:L$5000),0) -> 0 | M10: =IFERROR(SUMPRODUCT(('01_Transactions'!F$2:F$5000='90_Settings'!B2)*(YEAR('01_Transactions'!A$2:A$5000)=YEAR(DATE(YEAR(TODAY()),MONTH(TODAY())+(-1),1)))*(MONTH('01_Transactions'!A$2:A$5000)=MONTH(DATE(YEAR(TODAY()),MONTH(TODAY())+(-1),1)))*'01_Transactions'!L$2:L$5000),0) -> 0 | N10: =IFERROR(SUMPRODUCT(('01_Transactions'!F$2:F$5000='90_Settings'!B2)*(YEAR('01_Transactions'!A$2:A$5000)=YEAR(DATE(YEAR(TODAY()),MONTH(TODAY()),1)))*(MONTH('01_Transactions'!A$2:A$5000)=MONTH(DATE(YEAR(TODAY()),MONTH(TODAY()),1)))*'01_Transactions'!L$2:L$5000),0) -> 0
E11: =IFERROR('04_Pockets'!A2,"") -> 0 | F11: =IFERROR(SUMPRODUCT(('01_Transactions'!G$2:G$5000='04_Pockets'!A2)*'01_Transactions'!L$2:L$5000),0) -> 0 | H11: =IFERROR('90_Settings'!B3,"") -> 0 | I11: =IFERROR(SUMPRODUCT(('01_Transactions'!F$2:F$5000='90_Settings'!B3)*(YEAR('01_Transactions'!A$2:A$5000)=YEAR(DATE(YEAR(TODAY()),MONTH(TODAY())+(-5),1)))*(MONTH('01_Transactions'!A$2:A$5000)=MONTH(DATE(YEAR(TODAY()),MONTH(TODAY())+(-5),1)))*'01_Transactions'!L$2:L$5000),0) -> 0 | J11: =IFERROR(SUMPRODUCT(('01_Transactions'!F$2:F$5000='90_Settings'!B3)*(YEAR('01_Transactions'!A$2:A$5000)=YEAR(DATE(YEAR(TODAY()),MONTH(TODAY())+(-4),1)))*(MONTH('01_Transactions'!A$2:A$5000)=MONTH(DATE(YEAR(TODAY()),MONTH(TODAY())+(-4),1)))*'01_Transactions'!L$2:L$5000),0) -> 0 | K11: =IFERROR(SUMPRODUCT(('01_Transactions'!F$2:F$5000='90_Settings'!B3)*(YEAR('01_Transactions'!A$2:A$5000)=YEAR(DATE(YEAR(TODAY()),MONTH(TODAY())+(-3),1)))*(MONTH('01_Transactions'!A$2:A$5000)=MONTH(DATE(YEAR(TODAY()),MONTH(TODAY())+(-3),1)))*'01_Transactions'!L$2:L$5000),0) -> 0 | L11: =IFERROR(SUMPRODUCT(('01_Transactions'!F$2:F$5000='90_Settings'!B3)*(YEAR('01_Transactions'!A$2:A$5000)=YEAR(DATE(YEAR(TODAY()),MONTH(TODAY())+(-2),1)))*(MONTH('01_Transactions'!A$2:A$5000)=MONTH(DATE(YEAR(TODAY()),MONTH(TODAY())+(-2),1)))*'01_Transactions'!L$2:L$5000),0) -> 0 | M11: =IFERROR(SUMPRODUCT(('01_Transactions'!F$2:F$5000='90_Settings'!B3)*(YEAR('01_Transactions'!A$2:A$5000)=YEAR(DATE(YEAR(TODAY()),MONTH(TODAY())+(-1),1)))*(MONTH('01_Transactions'!A$2:A$5000)=MONTH(DATE(YEAR(TODAY()),MONTH(TODAY())+(-1),1)))*'01_Transactions'!L$2:L$5000),0) -> 0 | N11: =IFERROR(SUMPRODUCT(('01_Transactions'!F$2:F$5000='90_Settings'!B3)*(YEAR('01_Transactions'!A$2:A$5000)=YEAR(DATE(YEAR(TODAY()),MONTH(TODAY()),1)))*(MONTH('01_Transactions'!A$2:A$5000)=MONTH(DATE(YEAR(TODAY()),MONTH(TODAY()),1)))*'01_Transactions'!L$2:L$5000),0) -> 0
E12: =IFERROR('04_Pockets'!A3,"") -> 0 | F12: =IFERROR(SUMPRODUCT(('01_Transactions'!G$2:G$5000='04_Pockets'!A3)*'01_Transactions'!L$2:L$5000),0) -> 0 | H12: =IFERROR('90_Settings'!B4,"") -> 0 | I12: =IFERROR(SUMPRODUCT(('01_Transactions'!F$2:F$5000='90_Settings'!B4)*(YEAR('01_Transactions'!A$2:A$5000)=YEAR(DATE(YEAR(TODAY()),MONTH(TODAY())+(-5),1)))*(MONTH('01_Transactions'!A$2:A$5000)=MONTH(DATE(YEAR(TODAY()),MONTH(TODAY())+(-5),1)))*'01_Transactions'!L$2:L$5000),0) -> 0 | J12: =IFERROR(SUMPRODUCT(('01_Transactions'!F$2:F$5000='90_Settings'!B4)*(YEAR('01_Transactions'!A$2:A$5000)=YEAR(DATE(YEAR(TODAY()),MONTH(TODAY())+(-4),1)))*(MONTH('01_Transactions'!A$2:A$5000)=MONTH(DATE(YEAR(TODAY()),MONTH(TODAY())+(-4),1)))*'01_Transactions'!L$2:L$5000),0) -> 0 | K12: =IFERROR(SUMPRODUCT(('01_Transactions'!F$2:F$5000='90_Settings'!B4)*(YEAR('01_Transactions'!A$2:A$5000)=YEAR(DATE(YEAR(TODAY()),MONTH(TODAY())+(-3),1)))*(MONTH('01_Transactions'!A$2:A$5000)=MONTH(DATE(YEAR(TODAY()),MONTH(TODAY())+(-3),1)))*'01_Transactions'!L$2:L$5000),0) -> 0 | L12: =IFERROR(SUMPRODUCT(('01_Transactions'!F$2:F$5000='90_Settings'!B4)*(YEAR('01_Transactions'!A$2:A$5000)=YEAR(DATE(YEAR(TODAY()),MONTH(TODAY())+(-2),1)))*(MONTH('01_Transactions'!A$2:A$5000)=MONTH(DATE(YEAR(TODAY()),MONTH(TODAY())+(-2),1)))*'01_Transactions'!L$2:L$5000),0) -> 0 | M12: =IFERROR(SUMPRODUCT(('01_Transactions'!F$2:F$5000='90_Settings'!B4)*(YEAR('01_Transactions'!A$2:A$5000)=YEAR(DATE(YEAR(TODAY()),MONTH(TODAY())+(-1),1)))*(MONTH('01_Transactions'!A$2:A$5000)=MONTH(DATE(YEAR(TODAY()),MONTH(TODAY())+(-1),1)))*'01_Transactions'!L$2:L$5000),0) -> 0 | N12: =IFERROR(SUMPRODUCT(('01_Transactions'!F$2:F$5000='90_Settings'!B4)*(YEAR('01_Transactions'!A$2:A$5000)=YEAR(DATE(YEAR(TODAY()),MONTH(TODAY()),1)))*(MONTH('01_Transactions'!A$2:A$5000)=MONTH(DATE(YEAR(TODAY()),MONTH(TODAY()),1)))*'01_Transactions'!L$2:L$5000),0) -> 0
E13: =IFERROR('04_Pockets'!A4,"") -> 0 | F13: =IFERROR(SUMPRODUCT(('01_Transactions'!G$2:G$5000='04_Pockets'!A4)*'01_Transactions'!L$2:L$5000),0) -> 0 | H13: =IFERROR('90_Settings'!B5,"") -> 0 | I13: =IFERROR(SUMPRODUCT(('01_Transactions'!F$2:F$5000='90_Settings'!B5)*(YEAR('01_Transactions'!A$2:A$5000)=YEAR(DATE(YEAR(TODAY()),MONTH(TODAY())+(-5),1)))*(MONTH('01_Transactions'!A$2:A$5000)=MONTH(DATE(YEAR(TODAY()),MONTH(TODAY())+(-5),1)))*'01_Transactions'!L$2:L$5000),0) -> 0 | J13: =IFERROR(SUMPRODUCT(('01_Transactions'!F$2:F$5000='90_Settings'!B5)*(YEAR('01_Transactions'!A$2:A$5000)=YEAR(DATE(YEAR(TODAY()),MONTH(TODAY())+(-4),1)))*(MONTH('01_Transactions'!A$2:A$5000)=MONTH(DATE(YEAR(TODAY()),MONTH(TODAY())+(-4),1)))*'01_Transactions'!L$2:L$5000),0) -> 0 | K13: =IFERROR(SUMPRODUCT(('01_Transactions'!F$2:F$5000='90_Settings'!B5)*(YEAR('01_Transactions'!A$2:A$5000)=YEAR(DATE(YEAR(TODAY()),MONTH(TODAY())+(-3),1)))*(MONTH('01_Transactions'!A$2:A$5000)=MONTH(DATE(YEAR(TODAY()),MONTH(TODAY())+(-3),1)))*'01_Transactions'!L$2:L$5000),0) -> 0 | L13: =IFERROR(SUMPRODUCT(('01_Transactions'!F$2:F$5000='90_Settings'!B5)*(YEAR('01_Transactions'!A$2:A$5000)=YEAR(DATE(YEAR(TODAY()),MONTH(TODAY())+(-2),1)))*(MONTH('01_Transactions'!A$2:A$5000)=MONTH(DATE(YEAR(TODAY()),MONTH(TODAY())+(-2),1)))*'01_Transactions'!L$2:L$5000),0) -> 0 | M13: =IFERROR(SUMPRODUCT(('01_Transactions'!F$2:F$5000='90_Settings'!B5)*(YEAR('01_Transactions'!A$2:A$5000)=YEAR(DATE(YEAR(TODAY()),MONTH(TODAY())+(-1),1)))*(MONTH('01_Transactions'!A$2:A$5000)=MONTH(DATE(YEAR(TODAY()),MONTH(TODAY())+(-1),1)))*'01_Transactions'!L$2:L$5000),0) -> 0 | N13: =IFERROR(SUMPRODUCT(('01_Transactions'!F$2:F$5000='90_Settings'!B5)*(YEAR('01_Transactions'!A$2:A$5000)=YEAR(DATE(YEAR(TODAY()),MONTH(TODAY()),1)))*(MONTH('01_Transactions'!A$2:A$5000)=MONTH(DATE(YEAR(TODAY()),MONTH(TODAY()),1)))*'01_Transactions'!L$2:L$5000),0) -> 0
H14: =IFERROR('90_Settings'!B6,"") -> 0 | I14: =IFERROR(SUMPRODUCT(('01_Transactions'!F$2:F$5000='90_Settings'!B6)*(YEAR('01_Transactions'!A$2:A$5000)=YEAR(DATE(YEAR(TODAY()),MONTH(TODAY())+(-5),1)))*(MONTH('01_Transactions'!A$2:A$5000)=MONTH(DATE(YEAR(TODAY()),MONTH(TODAY())+(-5),1)))*'01_Transactions'!L$2:L$5000),0) -> 0 | J14: =IFERROR(SUMPRODUCT(('01_Transactions'!F$2:F$5000='90_Settings'!B6)*(YEAR('01_Transactions'!A$2:A$5000)=YEAR(DATE(YEAR(TODAY()),MONTH(TODAY())+(-4),1)))*(MONTH('01_Transactions'!A$2:A$5000)=MONTH(DATE(YEAR(TODAY()),MONTH(TODAY())+(-4),1)))*'01_Transactions'!L$2:L$5000),0) -> 0 | K14: =IFERROR(SUMPRODUCT(('01_Transactions'!F$2:F$5000='90_Settings'!B6)*(YEAR('01_Transactions'!A$2:A$5000)=YEAR(DATE(YEAR(TODAY()),MONTH(TODAY())+(-3),1)))*(MONTH('01_Transactions'!A$2:A$5000)=MONTH(DATE(YEAR(TODAY()),MONTH(TODAY())+(-3),1)))*'01_Transactions'!L$2:L$5000),0) -> 0 | L14: =IFERROR(SUMPRODUCT(('01_Transactions'!F$2:F$5000='90_Settings'!B6)*(YEAR('01_Transactions'!A$2:A$5000)=YEAR(DATE(YEAR(TODAY()),MONTH(TODAY())+(-2),1)))*(MONTH('01_Transactions'!A$2:A$5000)=MONTH(DATE(YEAR(TODAY()),MONTH(TODAY())+(-2),1)))*'01_Transactions'!L$2:L$5000),0) -> 0 | M14: =IFERROR(SUMPRODUCT(('01_Transactions'!F$2:F$5000='90_Settings'!B6)*(YEAR('01_Transactions'!A$2:A$5000)=YEAR(DATE(YEAR(TODAY()),MONTH(TODAY())+(-1),1)))*(MONTH('01_Transactions'!A$2:A$5000)=MONTH(DATE(YEAR(TODAY()),MONTH(TODAY())+(-1),1)))*'01_Transactions'!L$2:L$5000),0) -> 0 | N14: =IFERROR(SUMPRODUCT(('01_Transactions'!F$2:F$5000='90_Settings'!B6)*(YEAR('01_Transactions'!A$2:A$5000)=YEAR(DATE(YEAR(TODAY()),MONTH(TODAY()),1)))*(MONTH('01_Transactions'!A$2:A$5000)=MONTH(DATE(YEAR(TODAY()),MONTH(TODAY()),1)))*'01_Transactions'!L$2:L$5000),0) -> 0
H15: =IFERROR('90_Settings'!B7,"") -> 0 | I15: =IFERROR(SUMPRODUCT(('01_Transactions'!F$2:F$5000='90_Settings'!B7)*(YEAR('01_Transactions'!A$2:A$5000)=YEAR(DATE(YEAR(TODAY()),MONTH(TODAY())+(-5),1)))*(MONTH('01_Transactions'!A$2:A$5000)=MONTH(DATE(YEAR(TODAY()),MONTH(TODAY())+(-5),1)))*'01_Transactions'!L$2:L$5000),0) -> 0 | J15: =IFERROR(SUMPRODUCT(('01_Transactions'!F$2:F$5000='90_Settings'!B7)*(YEAR('01_Transactions'!A$2:A$5000)=YEAR(DATE(YEAR(TODAY()),MONTH(TODAY())+(-4),1)))*(MONTH('01_Transactions'!A$2:A$5000)=MONTH(DATE(YEAR(TODAY()),MONTH(TODAY())+(-4),1)))*'01_Transactions'!L$2:L$5000),0) -> 0 | K15: =IFERROR(SUMPRODUCT(('01_Transactions'!F$2:F$5000='90_Settings'!B7)*(YEAR('01_Transactions'!A$2:A$5000)=YEAR(DATE(YEAR(TODAY()),MONTH(TODAY())+(-3),1)))*(MONTH('01_Transactions'!A$2:A$5000)=MONTH(DATE(YEAR(TODAY()),MONTH(TODAY())+(-3),1)))*'01_Transactions'!L$2:L$5000),0) -> 0 | L15: =IFERROR(SUMPRODUCT(('01_Transactions'!F$2:F$5000='90_Settings'!B7)*(YEAR('01_Transactions'!A$2:A$5000)=YEAR(DATE(YEAR(TODAY()),MONTH(TODAY())+(-2),1)))*(MONTH('01_Transactions'!A$2:A$5000)=MONTH(DATE(YEAR(TODAY()),MONTH(TODAY())+(-2),1)))*'01_Transactions'!L$2:L$5000),0) -> 0 | M15: =IFERROR(SUMPRODUCT(('01_Transactions'!F$2:F$5000='90_Settings'!B7)*(YEAR('01_Transactions'!A$2:A$5000)=YEAR(DATE(YEAR(TODAY()),MONTH(TODAY())+(-1),1)))*(MONTH('01_Transactions'!A$2:A$5000)=MONTH(DATE(YEAR(TODAY()),MONTH(TODAY())+(-1),1)))*'01_Transactions'!L$2:L$5000),0) -> 0 | N15: =IFERROR(SUMPRODUCT(('01_Transactions'!F$2:F$5000='90_Settings'!B7)*(YEAR('01_Transactions'!A$2:A$5000)=YEAR(DATE(YEAR(TODAY()),MONTH(TODAY()),1)))*(MONTH('01_Transactions'!A$2:A$5000)=MONTH(DATE(YEAR(TODAY()),MONTH(TODAY()),1)))*'01_Transactions'!L$2:L$5000),0) -> 0

Sheet 01_Transactions
A1: Date | B1: Type | C1: Account | D1: Amount | E1: Currency | F1: Category | G1: Pocket | H1: Merchant | I1: Owner | J1: Note | K1: ID 🔒 | L1: BaseAmount 🔒 | M1: CreatedAt 🔒
A2: 2024-01-08 | B2: Expense | C2: OTP számla | D2: 39591 | E2: HUF | F2: Business befektetés | I2: Adam | J2: Mezek és táska | K2: TX-1448 | L2: =D2*N2 -> 0 | N2: =IF(E2="HUF", 1, IFERROR(VLOOKUP(A2&E2, '91_Data_ExRates'!A:D, 4, FALSE), 1)) -> 0
A3: 2024-01-22 | B3: Expense | C3: Készpénz | D3: 500 | E3: HUF | F3: Ajándék | I3: Adam | J3: Futár | K3: TX-1445 | L3: =D3*N3 -> 0 | N3: =IF(E3="HUF", 1, IFERROR(VLOOKUP(A3&E3, '91_Data_ExRates'!A:D, 4, FALSE), 1)) -> 0
A4: 2024-01-22 | B4: Expense | C4: OTP számla | D4: 220 | E4: HUF | F4: Közlekedés | I4: Adam | J4: Gdl | K4: TX-1446 | L4: =D4*N4 -> 0 | N4: =IF(E4="HUF", 1, IFERROR(VLOOKUP(A4&E4, '91_Data_ExRates'!A:D, 4, FALSE), 1)) -> 0
A5: 2024-01-22 | B5: Expense | C5: OTP számla | D5: 220 | E5: HUF | F5: Közlekedés | I5: Adam | J5: GDL busz | K5: TX-1447 | L5: =D5*N5 -> 0 | N5: =IF(E5="HUF", 1, IFERROR(VLOOKUP(A5&E5, '91_Data_ExRates'!A:D, 4, FALSE), 1)) -> 0
A6: 2024-01-23 | B6: Expense | C6: Készpénz | D6: 2000 | E6: HUF | F6: Étel-ital | I6: Adam | J6: Algir gyros @ Dönercos | K6: TX-1444 | L6: =D6*N6 -> 0 | N6: =IF(E6="HUF", 1, IFERROR(VLOOKUP(A6&E6, '91_Data_ExRates'!A:D, 4, FALSE), 1)) -> 0
A7: 2024-01-23 | B7: Expense | C7: Készpénz | D7: 850 | E7: HUF | F7: Luxus, szórakozás | I7: Adam | J7: Dreher @ pajta pub | K7: TX-1443 | L7: =D7*N7 -> 0 | N7: =IF(E7="HUF", 1, IFERROR(VLOOKUP(A7&E7, '91_Data_ExRates'!A:D, 4, FALSE), 1)) -> 0
A8: 2024-01-24 | B8: Expense | C8: OTP számla | D8: 220 | E8: HUF | F8: Közlekedés | I8: Adam | J8: Gdl | K8: TX-1442 | L8: =D8*N8 -> 0 | N8: =IF(E8="HUF", 1, IFERROR(VLOOKUP(A8&E8, '91_Data_ExRates'!A:D, 4, FALSE), 1)) -> 0
A9: 2024-01-25 | B9: Income | C9: OTP számla | D9: 15000 | E9: HUF | F9: Üzletelés | I9: Adam | J9: Juventus vendég mez | K9: TX-1519 | L9: =D9*N9 -> 0 | N9: =IF(E9="HUF", 1, IFERROR(VLOOKUP(A9&E9, '91_Data_ExRates'!A:D, 4, FALSE), 1)) -> 0
A10: 2024-01-26 | B10: Income | C10: Készpénz | D10: 50000 | E10: HUF | F10: Ajándék | I10: Adam | J10: Barcelona zsebpénz - Bözsi mama | K10: TX-1518 | L10: =D10*N10 -> 0 | N10: =IF(E10="HUF", 1, IFERROR(VLOOKUP(A10&E10, '91_Data_ExRates'!A:D, 4, FALSE), 1)) -> 0
A11: 2024-01-26 | B11: Income | C11: Készpénz | D11: 20000 | E11: HUF | F11: Ajándék | I11: Adam | J11: Barcelona zsebpénz - Zsuzsi mama | K11: TX-1517 | L11: =D11*N11 -> 0 | N11: =IF(E11="HUF", 1, IFERROR(VLOOKUP(A11&E11, '91_Data_ExRates'!A:D, 4, FALSE), 1)) -> 0
A12: 2024-02-01 | B12: Expense | C12: Készpénz | D12: 890 | E12: HUF | F12: Luxus, szórakozás | I12: Adam | J12: Sör @ Blokk | K12: TX-1441 | L12: =D12*N12 -> 0 | N12: =IF(E12="HUF", 1, IFERROR(VLOOKUP(A12&E12, '91_Data_ExRates'!A:D, 4, FALSE), 1)) -> 0
A13: 2024-02-01 | B13: Expense | C13: Készpénz | D13: 1490 | E13: HUF | F13: Luxus, szórakozás | I13: Adam | J13: Daiquiri @ Blokk | K13: TX-1440 | L13: =D13*N13 -> 0 | N13: =IF(E13="HUF", 1, IFERROR(VLOOKUP(A13&E13, '91_Data_ExRates'!A:D, 4, FALSE), 1)) -> 0
... A23: 2024-02-13 | B23: Expense | C23: OTP számla | D23: 2587 | E23: HUF | F23: Business befektetés | I23: Adam | J23: EUR átváltas költségei | K23: TX-1431 | L23: =D23*N23 -> 0 | N23: =IF(E23="HUF", 1, IFERROR(VLOOKUP(A23&E23, '91_Data_ExRates'!A:D, 4, FALSE), 1)) -> 0
A24: 2024-02-13 | B24: Transfer | C24: OTP számla | D24: 193641.55 | E24: HUF | I24: Adam | K24: TX-1551 | L24: =D24*N24 -> 0 | N24: =IF(E24="HUF", 1, IFERROR(VLOOKUP(A24&E24, '91_Data_ExRates'!A:D, 4, FALSE), 1)) -> 0
A25: 2024-02-15 | B25: Expense | C25: OTP számla | D25: 292 | E25: HUF | F25: Egyéb | I25: Adam | J25: Otp díj | K25: TX-1430 | L25: =D25*N25 -> 0 | N25: =IF(E25="HUF", 1, IFERROR(VLOOKUP(A25&E25, '91_Data_ExRates'!A:D, 4, FALSE), 1)) -> 0
A26: 2024-02-15 | B26: Transfer | C26: OTP számla | D26: 50000 | E26: HUF | I26: Adam | K26: TX-1550 | L26: =D26*N26 -> 0 | N26: =IF(E26="HUF", 1, IFERROR(VLOOKUP(A26&E26, '91_Data_ExRates'!A:D, 4, FALSE), 1)) -> 0
A27: 2024-02-16 | B27: Expense | C27: Készpénz | D27: 1900 | E27: HUF | F27: Étel-ital | I27: Adam | J27: Mekdo | K27: TX-1429 | L27: =D27*N27 -> 0 | N27: =IF(E27="HUF", 1, IFERROR(VLOOKUP(A27&E27, '91_Data_ExRates'!A:D, 4, FALSE), 1)) -> 0
A28: 2024-02-17 | B28: Expense | C28: Készpénz | D28: 680 | E28: HUF | F28: Luxus, szórakozás | I28: Adam | K28: TX-1428 | L28: =D28*N28 -> 0 | N28: =IF(E28="HUF", 1, IFERROR(VLOOKUP(A28&E28, '91_Data_ExRates'!A:D, 4, FALSE), 1)) -> 0
A29: 2024-02-21 | B29: Expense | C29: Készpénz | D29: 850 | E29: HUF | F29: Luxus, szórakozás | I29: Adam | J29: Pomyva nagyfröccs | K29: TX-1426 | L29: =D29*N29 -> 0 | N29: =IF(E29="HUF", 1, IFERROR(VLOOKUP(A29&E29, '91_Data_ExRates'!A:D, 4, FALSE), 1)) -> 0
A30: 2024-02-21 | B30: Expense | C30: Készpénz | D30: 850 | E30: HUF | F30: Luxus, szórakozás | I30: Adam | J30: Borpatika házmester | K30: TX-1427 | L30: =D30*N30 -> 0 | N30: =IF(E30="HUF", 1, IFERROR(VLOOKUP(A30&E30, '91_Data_ExRates'!A:D, 4, FALSE), 1)) -> 0
A31: 2024-02-21 | B31: Expense | C31: Készpénz | D31: 1600 | E31: HUF | F31: Étel-ital | I31: Adam | J31: Karimi gyrostál felezés | K31: TX-1425 | L31: =D31*N31 -> 0 | N31: =IF(E31="HUF", 1, IFERROR(VLOOKUP(A31&E31, '91_Data_ExRates'!A:D, 4, FALSE), 1)) -> 0
A32: 2024-02-23 | B32: Income | C32: Államkincstár | D32: 225644 | E32: HUF | F32: Kamat | I32: Adam | K32: TX-1514 | L32: =D32*N32 -> 0 | N32: =IF(E32="HUF", 1, IFERROR(VLOOKUP(A32&E32, '91_Data_ExRates'!A:D, 4, FALSE), 1)) -> 0
A33: 2024-02-23 | B33: Income | C33: Készpénz | D33: 20000 | E33: HUF | F33: Ajándék | I33: Adam | J33: Anya zsebpénz | K33: TX-1515 | L33: =D33*N33 -> 0 | N33: =IF(E33="HUF", 1, IFERROR(VLOOKUP(A33&E33, '91_Data_ExRates'!A:D, 4, FALSE), 1)) -> 0
A34: 2024-02-23 | B34: Expense | C34: Készpénz | D34: 20000 | E34: HUF | F34: Étel-ital | I34: Adam | J34: Timi hotpot | K34: TX-1424 | L34: =D34*N34 -> 0 | N34: =IF(E34="HUF", 1, IFERROR(VLOOKUP(A34&E34, '91_Data_ExRates'!A:D, 4, FALSE), 1)) -> 0
A35: 2024-03-01 | B35: Transfer | C35: Államkincstár | D35: 225644 | E35: HUF | I35: Adam | K35: TX-1549 | L35: =D35*N35 -> 0 | N35: =IF(E35="HUF", 1, IFERROR(VLOOKUP(A35&E35, '91_Data_ExRates'!A:D, 4, FALSE), 1)) -> 0
A36: 2024-03-02 | B36: Expense | C36: OTP számla | D36: 1590 | E36: HUF | F36: Luxus, szórakozás | I36: Adam | J36: Pogi @ MVM - kóla | K36: TX-1422 | L36: =D36*N36 -> 0 | N36: =IF(E36="HUF", 1, IFERROR(VLOOKUP(A36&E36, '91_Data_ExRates'!A:D, 4, FALSE), 1)) -> 0
A37: 2024-03-02 | B37: Expense | C37: OTP számla | D37: 190 | E37: HUF | F37: Közlekedés | I37: Adam | J37: Volán GDL | K37: TX-1423 | L37: =D37*N37 -> 0 | N37: =IF(E37="HUF", 1, IFERROR(VLOOKUP(A37&E37, '91_Data_ExRates'!A:D, 4, FALSE), 1)) -> 0
A38: 2024-03-04 | B38: Expense | C38: OTP számla | D38: 1790 | E38: HUF | F38: Luxus, szórakozás | I38: Adam | J38: Sör @ udvarROM | K38: TX-1421 | L38: =D38*N38 -> 0 | N38: =IF(E38="HUF", 1, IFERROR(VLOOKUP(A38&E38, '91_Data_ExRates'!A:D, 4, FALSE), 1)) -> 0
A39: 2024-03-06 | B39: Expense | C39: Készpénz | D39: 26000 | E39: HUF | F39: Étel-ital | I39: Adam | J39: Hotpot bevásárlás | K39: TX-1420 | L39: =D39*N39 -> 0 | N39: =IF(E39="HUF", 1, IFERROR(VLOOKUP(A39&E39, '91_Data_ExRates'!A:D, 4, FALSE), 1)) -> 0
A40: 2024-03-06 | B40: Income | C40: Ajándékutalvány | D40: 10000 | E40: HUF | F40: Ajándék | I40: Adam | J40: Ajándékutalvány makro xdd | K40: TX-1513 | L40: =D40*N40 -> 0 | N40: =IF(E40="HUF", 1, IFERROR(VLOOKUP(A40&E40, '91_Data_ExRates'!A:D, 4, FALSE), 1)) -> 0
A41: 2024-03-07 | B41: Expense | C41: Készpénz | D41: 1900 | E41: HUF | F41: Luxus, szórakozás | I41: Adam | J41: Két sör + borravaló | K41: TX-1419 | L41: =D41*N41 -> 0 | N41: =IF(E41="HUF", 1, IFERROR(VLOOKUP(A41&E41, '91_Data_ExRates'!A:D, 4, FALSE), 1)) -> 0
A42: 2024-03-07 | B42: Income | C42: OTP számla | D42: 160000 | E42: HUF | F42: Ösztöndíj | I42: Adam | J42: Kéthavi ösztöndíj | K42: TX-1512 | L42: =D42*N42 -> 0 | N42: =IF(E42="HUF", 1, IFERROR(VLOOKUP(A42&E42, '91_Data_ExRates'!A:D, 4, FALSE), 1)) -> 0
A43: 2024-03-07 | B43: Expense | C43: Készpénz | D43: 3700 | E43: HUF | F43: Étel-ital | I43: Adam | J43: tortilla + falafel tál @ Karimi | K43: TX-1418 | L43: =D43*N43 -> 0 | N43: =IF(E43="HUF", 1, IFERROR(VLOOKUP(A43&E43, '91_Data_ExRates'!A:D, 4, FALSE), 1)) -> 0
A44: 2024-03-08 | B44: Expense | C44: OTP számla | D44: 190 | E44: HUF | F44: Közlekedés | I44: Adam | J44: GDL | K44: TX-1417 | L44: =D44*N44 -> 0 | N44: =IF(E44="HUF", 1, IFERROR(VLOOKUP(A44&E44, '91_Data_ExRates'!A:D, 4, FALSE), 1)) -> 0
A45: 2024-03-09 | B45: Income | C45: Készpénz | D45: 3800 | E45: HUF | F45: Egyéb | I45: Adam | J45: hotpot | K45: TX-1510 | L45: =D45*N45 -> 0 | N45: =IF(E45="HUF", 1, IFERROR(VLOOKUP(A45&E45, '91_Data_ExRates'!A:D, 4, FALSE), 1)) -> 0
A46: 2024-03-09 | B46: Income | C46: OTP számla | D46: 21900 | E46: HUF | F46: Egyéb | I46: Adam | J46: Hotpot bevásárlás+torta törlesztés | K46: TX-1511 | L46: =D46*N46 -> 0 | N46: =IF(E46="HUF", 1, IFERROR(VLOOKUP(A46&E46, '91_Data_ExRates'!A:D, 4, FALSE), 1)) -> 0
A47: 2024-03-14 | B47: Expense | C47: Készpénz | D47: 1400 | E47: HUF | F47: Luxus, szórakozás | I47: Adam | J47: Staropramen @ ZICCER | K47: TX-1416 | L47: =D47*N47 -> 0 | N47: =IF(E47="HUF", 1, IFERROR(VLOOKUP(A47&E47, '91_Data_ExRates'!A:D, 4, FALSE), 1)) -> 0
A48: 2024-03-16 | B48: Expense | C48: OTP számla | D48: 190 | E48: HUF | F48: Közlekedés | I48: Adam | K48: TX-1415 | L48: =D48*N48 -> 0 | N48: =IF(E48="HUF", 1, IFERROR(VLOOKUP(A48&E48, '91_Data_ExRates'!A:D, 4, FALSE), 1)) -> 0
A49: 2024-03-17 | B49: Transfer | C49: Ajándékutalvány | D49: 10000 | E49: HUF | I49: Adam | J49: Anya trade | K49: TX-1548 | L49: =D49*N49 -> 0 | N49: =IF(E49="HUF", 1, IFERROR(VLOOKUP(A49&E49, '91_Data_ExRates'!A:D, 4, FALSE), 1)) -> 0
...

Sheet 02_Accounts
A1: Name | B1: Type | C1: Currency | D1: Owner | E1: OpeningBalance | F1: IsArchived | G1: _MongoID 🔒
A2: Készpénz | B2: Bank | C2: HUF | D2: Adam | E2: 869500 | F2: FALSE | G2: 6a04c8576297c4682dd5cacc
A3: OTP számla | B3: Bank | C3: HUF | D3: Adam | E3: 325521.18 | F3: FALSE | G3: 6a04c8576297c4682dd5cacf
A4: Revolut Pro | B4: Bank | C4: HUF | D4: Adam | E4: 0 | F4: FALSE | G4: 6a04c8586297c4682dd5cad4
A5: Valuták (EUR) | B5: Bank | C5: EUR | D5: Adam | E5: 14.81 | F5: FALSE | G5: 6a04c8636297c4682dd5cbb2
A6: PayPal | B6: Bank | C6: HUF | D6: Adam | E6: 8737 | F6: FALSE | G6: 6a04c8666297c4682dd5cbf2
A7: Valuták (BGN) | B7: Bank | C7: BGN | D7: Adam | E7: 4.3 | F7: FALSE | G7: 6a04c8686297c4682dd5cc24
A8: Nexo | B8: Bank | C8: EUR | D8: Adam | E8: -251.49 | F8: FALSE | G8: 6a04c8716297c4682dd5ccbf
A9: Ajándékutalvány | B9: Bank | C9: HUF | D9: Adam | E9: 0 | F9: FALSE | G9: 6a04c8726297c4682dd5cce4
A10: Államkincstár | B10: Bank | C10: HUF | D10: Adam | E10: 1350000 | F10: FALSE | G10: 6a04c8726297c4682dd5cce6
A11: Wise | B11: Bank | C11: USD | D11: Adam | E11: -10.86 | F11: FALSE | G11: 6a04c8736297c4682dd5ccee
A12: Lightyear TBSZ | B12: Bank | C12: HUF | D12: Adam | E12: 0 | F12: FALSE | G12: 6a04c8736297c4682dd5ccf3
A13: Dapper wallet | B13: Bank | C13: USD | D13: Adam | E13: 521.22 | F13: FALSE | G13: 6a04c8746297c4682dd5cd05
A14: Laptop kaució | B14: Bank | C14: HUF | D14: Adam | E14: 0 | F14: FALSE | G14: 6a04c8746297c4682dd5cd0a

Sheet 03_BudgetsGoals
A1: Name | B1: Type | C1: Owner | D1: Target | E1: Period | F1: Note | G1: Deadline
A2: Élelmiszer | B2: Budget | C2: Adam | D2: 0 | E2: Monthly
A3: Szórakozás | B3: Budget | C3: Adam | D3: 0 | E3: Monthly
A4: Vésztartalék | B4: Goal | C4: Adam | D4: 0

Sheet 04_Pockets
A1: Pocket | B1: Owner | C1: Currency | D1: Target | E1: _MongoID 🔒
A2: Bari 2026 | B2: Adam | C2: HUF | D2: 200000 | E2: 6a05bfb43fc100a238d0b0df
A3: Vésztartalék | B3: Adam | C3: HUF | D3: 400000 | E3: 6a05c55603740ac92d5c4e54
A4: Hosszútávú | B4: Adam | C4: HUF | D4: 2000000 | E4: 6a05c5b803740ac92d5c4e56

Sheet 90_Settings
A1: People | B1: Categories | C1: Merchants | D1: Tags
A2: Adam | B2: Étel-ital | C2: Lidl | D2: Nyaralás
B3: Utazás | C3: Netflix | D3: Munka
B4: VitaSteps | C4: Spotify | D4: Ajándék
B5: Luxus, szórakozás | C5: Amazon
B6: Közlekedés
B7: Fejlődés, befektetés
B8: Egészség
B9: Egyéb
B10: Business befektetés
B11: Fizetés
B12: Ajándék
B13: Kamat
B14: Ösztöndíj
B15: Üzletelés

Sheet 91_Data_ExRates
A1: LookupKey 🔒 | B1: Date | C1: Currency | D1: Rate_to_HUF
A2: 2026-05-13AUD | B2: 2026-05-13 | C2: AUD | D2: 221.9953
A3: 2026-05-13BRL | B3: 2026-05-13 | C3: BRL | D3: 62.437988
A4: 2026-05-13CAD | B4: 2026-05-13 | C4: CAD | D4: 223.64237
A5: 2026-05-13CHF | B5: 2026-05-13 | C5: CHF | D5: 391.80775
A6: 2026-05-13CNY | B6: 2026-05-13 | C6: CNY | D6: 45.087737
A7: 2026-05-13CZK | B7: 2026-05-13 | C7: CZK | D7: 14.732821
A8: 2026-05-13DKK | B8: 2026-05-13 | C8: DKK | D8: 47.994327
A9: 2026-05-13GBP | B9: 2026-05-13 | C9: GBP | D9: 413.66346
A10: 2026-05-13HKD | B10: 2026-05-13 | C10: HKD | D10: 39.101761
A11: 2026-05-13IDR | B11: 2026-05-13 | C11: IDR | D11: 0.0175
A12: 2026-05-13ILS | B12: 2026-05-13 | C12: ILS | D12: 105.2956
A13: 2026-05-13INR | B13: 2026-05-13 | C13: INR | D13: 3.200413
... A5669: 2026-07-25ZWL | B5669: 2026-07-25 | C5669: ZWL | D5669: 11.926791

Sheet 91_Data_IDMap
A1: Sheet | B1: Name | C1: MongoID
A2: 02_Accounts | B2: Készpénz | C2: 6a04c8576297c4682dd5cacc
A3: 02_Accounts | B3: OTP számla | C3: 6a04c8576297c4682dd5cacf
A4: 02_Accounts | B4: Revolut Pro | C4: 6a04c8586297c4682dd5cad4
A5: 02_Accounts | B5: Valuták (EUR) | C5: 6a04c8636297c4682dd5cbb2
A6: 02_Accounts | B6: PayPal | C6: 6a04c8666297c4682dd5cbf2
A7: 02_Accounts | B7: Valuták (BGN) | C7: 6a04c8686297c4682dd5cc24
A8: 02_Accounts | B8: Nexo | C8: 6a04c8716297c4682dd5ccbf
A9: 02_Accounts | B9: Ajándékutalvány | C9: 6a04c8726297c4682dd5cce4
A10: 02_Accounts | B10: Államkincstár | C10: 6a04c8726297c4682dd5cce6
A11: 02_Accounts | B11: Wise | C11: 6a04c8736297c4682dd5ccee
A12: 02_Accounts | B12: Lightyear TBSZ | C12: 6a04c8736297c4682dd5ccf3
... A14: 02_Accounts | B14: Laptop kaució | C14: 6a04c8746297c4682dd5cd0a
